<?xml version="1.0"?>
<robot name="camera">

  <!-- Chassis -->
  <link name="chassis">
    <inertial>
      <mass value="1.14395"/>
      <origin xyz="0 0 0" rpy="0 0 0"/>
      <inertia ixx="0.126164" ixy="0" ixz="0" iyy="0.416519" iyz="0" izz="0.481014"/>
    </inertial>


    <visual>
      <origin xyz="0 0 0.25" rpy="0 0 0"/>
      <geometry>
        <box size="2.0 1.0 0.5"/>
      </geometry>
      <material name="Blue">
        <color rgba="0.0 0.0 1.0 1"/>
      </material>
    </visual>

    <collision>
      <origin xyz="0 0 0.25" rpy="0 0 0"/>
      <geometry>
        <box size="2.0 1.0 0.5"/>
      </geometry>
    </collision>

  </link>

  <!--camera link-->
  <link name="camera1">
    <visual>
        <geometry>
            <box size="0.09 0.09 0.09"/>
        </geometry>
        <material name="red"/>
    </visual>
    <collision>
        <geometry>
            <box size="0.09 0.09 0.09"/>
        </geometry>
    </collision>
    <inertial>
        <mass value="0.1"/>
        <inertia ixx="0.001" ixy="0" ixz="0" iyy="0.001" iyz="0" izz="0.001"/>
    </inertial>
  </link>


  <!-- Left Wheel -->
  <link name="left_wheel">
    <inertial>
      <mass value="2"/>
      <origin xyz="0 0 0" rpy="0 0 0"/>
      <inertia ixx="0.145833" ixy="0" ixz="0" iyy="0.145833" iyz="0" izz="0.125"/>
    </inertial>
    <visual>
      <geometry>
        <cylinder length="0.2" radius="0.4"/>
      </geometry>
      <material name="Red">
        <color rgba="1.0 0.0 0.0 1"/>
      </material>
    </visual>
    <collision>
      <geometry>
        <cylinder length="0.2" radius="0.4"/>
      </geometry>
    </collision>
  </link>

  <!-- Right Wheel -->
  <link name="right_wheel">
    <inertial>
      <mass value="1"/>
      <origin xyz="0 0 0" rpy="0 0 0"/>
      <inertia ixx="0.145833" ixy="0" ixz="0" iyy="0.145833" iyz="0" izz="0.125"/>
    </inertial>
    <visual>
      <geometry>
        <cylinder length="0.2" radius="0.4"/>
      </geometry>
      <material name="Red">
        <color rgba="1.0 0.0 0.0 1"/>
      </material>
    </visual>
    <collision>
      <geometry>
        <cylinder length="0.2" radius="0.4"/>
      </geometry>
    </collision>
  </link>

  <!-- Caster Wheel -->
  <link name="caster">
    <inertial>
      <mass value="1"/>
      <origin xyz="0 0 0" rpy="0 0 0"/>
      <inertia ixx="0.1" ixy="0" ixz="0" iyy="0.1" iyz="0" izz="0.1"/>
    </inertial>
    <visual>
      <geometry>
        <sphere radius="0.2"/>
      </geometry>
      <material name="Green">
        <color rgba="0.0 1.0 0.0 1"/>
      </material>
    </visual>
    <collision>
      <geometry>
        <sphere radius="0.2"/>
      </geometry>
    </collision>
  </link>

  <!-- Joints -->
  <joint name="left_wheel_joint" type="continuous">
    <origin xyz="-0.5 0.6 0" rpy="-1.5707 0 0"/>
    <parent link="chassis"/>
    <child link="left_wheel"/>
    <axis xyz="0 0 1"/>
  </joint>

  <joint name="right_wheel_joint" type="continuous">
    <origin xyz="-0.5 -0.6 0" rpy="-1.5707 0 0"/>
    <parent link="chassis"/>
    <child link="right_wheel"/>
    <axis xyz="0 0 1"/>
  </joint>

  <joint name="caster_wheel" type="fixed">
    <origin xyz="0.8 0 -0.2" rpy="0 0 0"/>
    <parent link="chassis"/>
    <child link="caster"/>
  </joint>

  <!-- Camera Joint -->
  <joint name="camera_joint" type="fixed">
    <parent link="chassis"/>
    <child link="camera1"/>
    <origin xyz="0.27 0 0.5" rpy="0 0 0"/>
    <axis xyz="0 0 1"/>
  </joint>

  <gazebo>
    <plugin
      filename="gz-sim-diff-drive-system"
      name="gz::sim::systems::DiffDrive">
      <left_joint>left_wheel_joint</left_joint>
      <right_joint>right_wheel_joint</right_joint>
      <wheel_separation>1.2</wheel_separation>
      <wheel_radius>0.4</wheel_radius>
      <odom_publish_frequency>1</odom_publish_frequency>
      <topic>cmd_vel</topic>
      <command_topic>cmd_vel</command_topic>
      <publish_odom>true</publish_odom>
      <publish_odom_tf>true</publish_odom_tf>
      <publish_wheel_tf>true</publish_wheel_tf>
      <odometry_topic>odom</odometry_topic>
      <odometry_frame>odom</odometry_frame>
      <robot_base_frame>chassis</robot_base_frame>
    </plugin>
    <plugin filename="gz-sim-joint-state-publisher-system" name="gz::sim::systems::JointStatePublisher">
      <update_rate>50</update_rate>
      <joint_name>left_wheel_joint</joint_name>
      <joint_name>right_wheel_joint</joint_name>
      <topic>joint_states</topic>
      <update_rate>30</update_rate>
    </plugin>
    <plugin
      filename="gz-sim-pose-publisher-system"
      name="gz::sim::systems::PosePublisher">
      <publish_link_pose>true</publish_link_pose>
      <use_pose_vector_msg>true</use_pose_vector_msg>
      <static_publisher>true</static_publisher>
      <static_update_frequency>1</static_update_frequency>
    </plugin>
  </gazebo>
  <!-- Camera Plugin -->
  <gazebo reference="camera1">
    <sensor type="camera" name="camera">
        <update_rate>30.0</update_rate>
        <camera name="head">
            <camera_info_topic>camera/camera_info</camera_info_topic>
            <horizontal_fov>1.3962634</horizontal_fov>
            <image>
                <width>800</width>
                <height>600</height>
                <format>R8G8B8</format>
            </image>
            <clip>
                <near>0.02</near>
                <far>300</far>
            </clip>
            <noise>
                <type>gaussian</type>
                <mean>0.0</mean>
                <stddev>0.007</stddev>
            </noise>
        </camera>
        <topic>camera/image_raw</topic>
        <gz_frame_id>camera</gz_frame_id>
    </sensor>
  </gazebo>

</robot>
